Workbook
Name ListaEstado: Listas!$S$2:$S$28
Name ListaSDR: Listas!$A$2:$A$13
Name ListaSetor: Listas!$K$2:$K$35
Name ListaSimNao: Listas!$E$2:$E$3
Name ListaStatus: Listas!$C$2:$C$5
Name ListaStatusAtividade: Listas!$O$2:$O$3
Name ListaStatusProposta: Listas!$G$2:$G$5
Name ListaTabulacaoLigacao: Listas!$Q$2:$Q$9
Name ListaTipoProposta: Listas!$M$2:$M$69
Name ListaTipoVisao: Listas!$I$2:$I$4

Sheet Visão_Geral
A1: VISÃO GERAL COMERCIAL
A2: Escolha o tipo de visão e a data de referência. Tudo abaixo atualiza sozinho.
A4: Tipo de Visão: | B4: Mensal | D4: Início período | E4: =IF($B$4="Diário",$B$5,IF($B$4="Semanal",$B$5-WEEKDAY($B$5,3),DATE(YEAR($B$5),MONTH($B$5),1))) -> 46204 | G4: Mês ref. início | H4: =DATE(YEAR($B$5),MONTH($B$5),1) -> 46204
A5: Data de referência: | B5: =TODAY() -> 46222 | D5: Fim período | E5: =IF($B$4="Diário",$B$5,IF($B$4="Semanal",$B$5-WEEKDAY($B$5,3)+6,EOMONTH($B$5,0))) -> 46234 | G5: Mês ref. fim | H5: =EOMONTH($B$5,0) -> 46234
A7: NÚMEROS DO PERÍODO SELECIONADO
A8: LIGAÇÕES | C8: MARCADAS | E8: REALIZADAS | G8: CANCELADAS
A9: =COUNTIFS(TLigacoes[Data],">="&Visão_Geral!$E$4,TLigacoes[Data],"<="&Visão_Geral!$E$5,TLigacoes[Status],"Finalizada") -> 237 | C9: =COUNTIFS(TReunioes[Data da Reunião],">="&Visão_Geral!$E$4,TReunioes[Data da Reunião],"<="&Visão_Geral!$E$5) -> 25 | E9: =COUNTIFS(TReunioes[Data da Reunião],">="&Visão_Geral!$E$4,TReunioes[Data da Reunião],"<="&Visão_Geral!$E$5,TReunioes[Status],"Realizada") -> 12 | G9: =COUNTIFS(TReunioes[Data da Reunião],">="&Visão_Geral!$E$4,TReunioes[Data da Reunião],"<="&Visão_Geral!$E$5,TReunioes[Status],"Cancelada") -> 9
A11: REMANEJADAS | C11: PROPOSTAS ENVIADAS | E11: NEGÓCIOS FECHADOS
A12: =COUNTIFS(TReunioes[Data da Reunião],">="&Visão_Geral!$E$4,TReunioes[Data da Reunião],"<="&Visão_Geral!$E$5,TReunioes[Status],"Remanejada") -> 0 | C12: =COUNTIFS(TPropostas[Data de Envio],">="&Visão_Geral!$E$4,TPropostas[Data de Envio],"<="&Visão_Geral!$E$5) -> 11 | E12: =COUNTIFS(TPropostas[Status],"Aprovada",TPropostas[Data de Retorno],">="&Visão_Geral!$E$4,TPropostas[Data de Retorno],"<="&Visão_Geral!$E$5) -> 2
A15: TAXAS DE CONVERSÃO (período selecionado)
A17: LIGAÇÃO → MARCADA | C17: MARCADA → REALIZADA | E17: REALIZADA → PROPOSTA | G17: PROPOSTA → FECHAMENTO
A18: =IFERROR(COUNTIFS(TReunioes[Data da Reunião],">="&Visão_Geral!$E$4,TReunioes[Data da Reunião],"<="&Visão_Geral!$E$5)/COUNTIFS(TLigacoes[Data],">="&Visão_Geral!$E$4,TLigacoes[Data],"<="&Visão_Geral!$E$5,TLigacoes[Status],"Finalizada"),0) -> 0.10548523 | C18: =IFERROR(COUNTIFS(TReunioes[Data da Reunião],">="&Visão_Geral!$E$4,TReunioes[Data da Reunião],"<="&Visão_Geral!$E$5,TReunioes[Status],"Realizada")/COUNTIFS(TReunioes[Data da Reunião],">="&Visão_Geral!$E$4,TReunioes[Data da Reunião],"<="&Visão_Geral!$E$5),0) -> 0.48 | E18: =IFERROR(COUNTIFS(TPropostas[Data de Envio],">="&Visão_Geral!$E$4,TPropostas[Data de Envio],"<="&Visão_Geral!$E$5)/COUNTIFS(TReunioes[Data da Reunião],">="&Visão_Geral!$E$4,TReunioes[Data da Reunião],"<="&Visão_Geral!$E$5,TReunioes[Status],"Realizada"),0) -> 0.91666667 | G18: =IFERROR(COUNTIFS(TPropostas[Status],"Aprovada",TPropostas[Data de Retorno],">="&Visão_Geral!$E$4,TPropostas[Data de Retorno],"<="&Visão_Geral!$E$5)/COUNTIFS(TPropostas[Data de Envio],">="&Visão_Geral!$E$4,TPropostas[Data de Envio],"<="&Visão_Geral!$E$5),0) -> 0.18181818
A20: TAXA DE NO SHOW | C20: TAXA DE REMANEJAMENTO | E20: GERAL: MARCADA → FECHAMENTO
A21: =IFERROR(COUNTIFS(TReunioes[Data da Reunião],">="&Visão_Geral!$E$4,TReunioes[Data da Reunião],"<="&Visão_Geral!$E$5,TReunioes[Status],"Cancelada")/COUNTIFS(TReunioes[Data da Reunião],">="&Visão_Geral!$E$4,TReunioes[Data da Reunião],"<="&Visão_Geral!$E$5),0) -> 0.36 | C21: =IFERROR(COUNTIFS(TReunioes[Data da Reunião],">="&Visão_Geral!$E$4,TReunioes[Data da Reunião],"<="&Visão_Geral!$E$5,TReunioes[Status],"Remanejada")/COUNTIFS(TReunioes[Data da Reunião],">="&Visão_Geral!$E$4,TReunioes[Data da Reunião],"<="&Visão_Geral!$E$5),0) -> 0 | E21: =IFERROR(COUNTIFS(TPropostas[Status],"Aprovada",TPropostas[Data de Retorno],">="&Visão_Geral!$E$4,TPropostas[Data de Retorno],"<="&Visão_Geral!$E$5)/COUNTIFS(TReunioes[Data da Reunião],">="&Visão_Geral!$E$4,TReunioes[Data da Reunião],"<="&Visão_Geral!$E$5),0) -> 0.08
A24: META MENSAL (mês da data de referência) — quanto falta para bater
A25: Métrica | B25: Meta do Mês | C25: Realizado | D25: Faltam | E25: % Atingido
A26: Reuniões Agendadas | B26: 120 | C26: =COUNTIFS(TReunioes[Data da Reunião],">="&Visão_Geral!$H$4,TReunioes[Data da Reunião],"<="&Visão_Geral!$H$5) -> 25 | D26: =MAX($B26-$C26,0) -> 95 | E26: =IFERROR($C26/$B26,0) -> 0.20833333
A27: Reuniões Realizadas | B27: 64 | C27: =COUNTIFS(TReunioes[Data da Reunião],">="&Visão_Geral!$H$4,TReunioes[Data da Reunião],"<="&Visão_Geral!$H$5,TReunioes[Status],"Realizada") -> 12 | D27: =MAX($B27-$C27,0) -> 52 | E27: =IFERROR($C27/$B27,0) -> 0.1875
A28: Negócios Fechados | B28: 15 | C28: =COUNTIFS(TPropostas[Status],"Aprovada",TPropostas[Data de Retorno],">="&Visão_Geral!$H$4,TPropostas[Data de Retorno],"<="&Visão_Geral!$H$5) -> 2 | D28: =MAX($B28-$C28,0) -> 13 | E28: =IFERROR($C28/$B28,0) -> 0.13333333
A29: * Edite a coluna "Meta do Mês" (em azul) com os números que quiser bater.
A32: RANKING POR SDR (período selecionado)
A33: SDR | B33: Ligações | C33: Marcadas | D33: Realizadas | E33: Canceladas | F33: Remanejadas | G33: Propostas | H33: Fechados
A34: Larissa Santos - Filial Porto Alegre | B34: =COUNTIFS(TLigacoes[Data],">="&Visão_Geral!$E$4,TLigacoes[Data],"<="&Visão_Geral!$E$5,TLigacoes[Status],"Finalizada",TLigacoes[SDR],$A34) -> 0 | C34: =COUNTIFS(TReunioes[Data da Reunião],">="&Visão_Geral!$E$4,TReunioes[Data da Reunião],"<="&Visão_Geral!$E$5,TReunioes[SDR],$A34) -> 0 | D34: =COUNTIFS(TReunioes[Data da Reunião],">="&Visão_Geral!$E$4,TReunioes[Data da Reunião],"<="&Visão_Geral!$E$5,TReunioes[SDR],$A34,TReunioes[Status],"Realizada") -> 0 | E34: =COUNTIFS(TReunioes[Data da Reunião],">="&Visão_Geral!$E$4,TReunioes[Data da Reunião],"<="&Visão_Geral!$E$5,TReunioes[SDR],$A34,TReunioes[Status],"Cancelada") -> 0 | F34: =COUNTIFS(TReunioes[Data da Reunião],">="&Visão_Geral!$E$4,TReunioes[Data da Reunião],"<="&Visão_Geral!$E$5,TReunioes[SDR],$A34,TReunioes[Status],"Remanejada") -> 0 | G34: =COUNTIFS(TPropostas[Data de Envio],">="&Visão_Geral!$E$4,TPropostas[Data de Envio],"<="&Visão_Geral!$E$5,TPropostas[SDR],$A34) -> 0 | H34: =COUNTIFS(TPropostas[Status],"Aprovada",TPropostas[Data de Retorno],">="&Visão_Geral!$E$4,TPropostas[Data de Retorno],"<="&Visão_Geral!$E$5,TPropostas[SDR],$A34) -> 0
A35: Railanne Rosario do Carmo - Filial Alpha | B35: =COUNTIFS(TLigacoes[Data],">="&Visão_Geral!$E$4,TLigacoes[Data],"<="&Visão_Geral!$E$5,TLigacoes[Status],"Finalizada",TLigacoes[SDR],$A35) -> 0 | C35: =COUNTIFS(TReunioes[Data da Reunião],">="&Visão_Geral!$E$4,TReunioes[Data da Reunião],"<="&Visão_Geral!$E$5,TReunioes[SDR],$A35) -> 0 | D35: =COUNTIFS(TReunioes[Data da Reunião],">="&Visão_Geral!$E$4,TReunioes[Data da Reunião],"<="&Visão_Geral!$E$5,TReunioes[SDR],$A35,TReunioes[Status],"Realizada") -> 0 | E35: =COUNTIFS(TReunioes[Data da Reunião],">="&Visão_Geral!$E$4,TReunioes[Data da Reunião],"<="&Visão_Geral!$E$5,TReunioes[SDR],$A35,TReunioes[Status],"Cancelada") -> 0 | F35: =COUNTIFS(TReunioes[Data da Reunião],">="&Visão_Geral!$E$4,TReunioes[Data da Reunião],"<="&Visão_Geral!$E$5,TReunioes[SDR],$A35,TReunioes[Status],"Remanejada") -> 0 | G35: =COUNTIFS(TPropostas[Data de Envio],">="&Visão_Geral!$E$4,TPropostas[Data de Envio],"<="&Visão_Geral!$E$5,TPropostas[SDR],$A35) -> 0 | H35: =COUNTIFS(TPropostas[Status],"Aprovada",TPropostas[Data de Retorno],">="&Visão_Geral!$E$4,TPropostas[Data de Retorno],"<="&Visão_Geral!$E$5,TPropostas[SDR],$A35) -> 0
A36: Maria Furtado - Filial RS | B36: =COUNTIFS(TLigacoes[Data],">="&Visão_Geral!$E$4,TLigacoes[Data],"<="&Visão_Geral!$E$5,TLigacoes[Status],"Finalizada",TLigacoes[SDR],$A36) -> 0 | C36: =COUNTIFS(TReunioes[Data da Reunião],">="&Visão_Geral!$E$4,TReunioes[Data da Reunião],"<="&Visão_Geral!$E$5,TReunioes[SDR],$A36) -> 0 | D36: =COUNTIFS(TReunioes[Data da Reunião],">="&Visão_Geral!$E$4,TReunioes[Data da Reunião],"<="&Visão_Geral!$E$5,TReunioes[SDR],$A36,TReunioes[Status],"Realizada") -> 0 | E36: =COUNTIFS(TReunioes[Data da Reunião],">="&Visão_Geral!$E$4,TReunioes[Data da Reunião],"<="&Visão_Geral!$E$5,TReunioes[SDR],$A36,TReunioes[Status],"Cancelada") -> 0 | F36: =COUNTIFS(TReunioes[Data da Reunião],">="&Visão_Geral!$E$4,TReunioes[Data da Reunião],"<="&Visão_Geral!$E$5,TReunioes[SDR],$A36,TReunioes[Status],"Remanejada") -> 0 | G36: =COUNTIFS(TPropostas[Data de Envio],">="&Visão_Geral!$E$4,TPropostas[Data de Envio],"<="&Visão_Geral!$E$5,TPropostas[SDR],$A36) -> 0 | H36: =COUNTIFS(TPropostas[Status],"Aprovada",TPropostas[Data de Retorno],">="&Visão_Geral!$E$4,TPropostas[Data de Retorno],"<="&Visão_Geral!$E$5,TPropostas[SDR],$A36) -> 0
A37: Ana Belle - Filial PR | B37: =COUNTIFS(TLigacoes[Data],">="&Visão_Geral!$E$4,TLigacoes[Data],"<="&Visão_Geral!$E$5,TLigacoes[Status],"Finalizada",TLigacoes[SDR],$A37) -> 0 | C37: =COUNTIFS(TReunioes[Data da Reunião],">="&Visão_Geral!$E$4,TReunioes[Data da Reunião],"<="&Visão_Geral!$E$5,TReunioes[SDR],$A37) -> 0 | D37: =COUNTIFS(TReunioes[Data da Reunião],">="&Visão_Geral!$E$4,TReunioes[Data da Reunião],"<="&Visão_Geral!$E$5,TReunioes[SDR],$A37,TReunioes[Status],"Realizada") -> 0 | E37: =COUNTIFS(TReunioes[Data da Reunião],">="&Visão_Geral!$E$4,TReunioes[Data da Reunião],"<="&Visão_Geral!$E$5,TReunioes[SDR],$A37,TReunioes[Status],"Cancelada") -> 0 | F37: =COUNTIFS(TReunioes[Data da Reunião],">="&Visão_Geral!$E$4,TReunioes[Data da Reunião],"<="&Visão_Geral!$E$5,TReunioes[SDR],$A37,TReunioes[Status],"Remanejada") -> 0 | G37: =COUNTIFS(TPropostas[Data de Envio],">="&Visão_Geral!$E$4,TPropostas[Data de Envio],"<="&Visão_Geral!$E$5,TPropostas[SDR],$A37) -> 0 | H37: =COUNTIFS(TPropostas[Status],"Aprovada",TPropostas[Data de Retorno],">="&Visão_Geral!$E$4,TPropostas[Data de Retorno],"<="&Visão_Geral!$E$5,TPropostas[SDR],$A37) -> 0
A38: Lawanny Souza Brasil Luz - Filial Alpha | B38: =COUNTIFS(TLigacoes[Data],">="&Visão_Geral!$E$4,TLigacoes[Data],"<="&Visão_Geral!$E$5,TLigacoes[Status],"Finalizada",TLigacoes[SDR],$A38) -> 0 | C38: =COUNTIFS(TReunioes[Data da Reunião],">="&Visão_Geral!$E$4,TReunioes[Data da Reunião],"<="&Visão_Geral!$E$5,TReunioes[SDR],$A38) -> 0 | D38: =COUNTIFS(TReunioes[Data da Reunião],">="&Visão_Geral!$E$4,TReunioes[Data da Reunião],"<="&Visão_Geral!$E$5,TReunioes[SDR],$A38,TReunioes[Status],"Realizada") -> 0 | E38: =COUNTIFS(TReunioes[Data da Reunião],">="&Visão_Geral!$E$4,TReunioes[Data da Reunião],"<="&Visão_Geral!$E$5,TReunioes[SDR],$A38,TReunioes[Status],"Cancelada") -> 0 | F38: =COUNTIFS(TReunioes[Data da Reunião],">="&Visão_Geral!$E$4,TReunioes[Data da Reunião],"<="&Visão_Geral!$E$5,TReunioes[SDR],$A38,TReunioes[Status],"Remanejada") -> 0 | G38: =COUNTIFS(TPropostas[Data de Envio],">="&Visão_Geral!$E$4,TPropostas[Data de Envio],"<="&Visão_Geral!$E$5,TPropostas[SDR],$A38) -> 0 | H38: =COUNTIFS(TPropostas[Status],"Aprovada",TPropostas[Data de Retorno],">="&Visão_Geral!$E$4,TPropostas[Data de Retorno],"<="&Visão_Geral!$E$5,TPropostas[SDR],$A38) -> 0
A39: Ana Karolayne - Matriz SP | B39: =COUNTIFS(TLigacoes[Data],">="&Visão_Geral!$E$4,TLigacoes[Data],"<="&Visão_Geral!$E$5,TLigacoes[Status],"Finalizada",TLigacoes[SDR],$A39) -> 92 | C39: =COUNTIFS(TReunioes[Data da Reunião],">="&Visão_Geral!$E$4,TReunioes[Data da Reunião],"<="&Visão_Geral!$E$5,TReunioes[SDR],$A39) -> 11 | D39: =COUNTIFS(TReunioes[Data da Reunião],">="&Visão_Geral!$E$4,TReunioes[Data da Reunião],"<="&Visão_Geral!$E$5,TReunioes[SDR],$A39,TReunioes[Status],"Realizada") -> 6 | E39: =COUNTIFS(TReunioes[Data da Reunião],">="&Visão_Geral!$E$4,TReunioes[Data da Reunião],"<="&Visão_Geral!$E$5,TReunioes[SDR],$A39,TReunioes[Status],"Cancelada") -> 5 | F39: =COUNTIFS(TReunioes[Data da Reunião],">="&Visão_Geral!$E$4,TReunioes[Data da Reunião],"<="&Visão_Geral!$E$5,TReunioes[SDR],$A39,TReunioes[Status],"Remanejada") -> 0 | G39: =COUNTIFS(TPropostas[Data de Envio],">="&Visão_Geral!$E$4,TPropostas[Data de Envio],"<="&Visão_Geral!$E$5,TPropostas[SDR],$A39) -> 2 | H39: =COUNTIFS(TPropostas[Status],"Aprovada",TPropostas[Data de Retorno],">="&Visão_Geral!$E$4,TPropostas[Data de Retorno],"<="&Visão_Geral!$E$5,TPropostas[SDR],$A39) -> 0
A40: Kailany Santos da Silva - Matriz SP | B40: =COUNTIFS(TLigacoes[Data],">="&Visão_Geral!$E$4,TLigacoes[Data],"<="&Visão_Geral!$E$5,TLigacoes[Status],"Finalizada",TLigacoes[SDR],$A40) -> 111 | C40: =COUNTIFS(TReunioes[Data da Reunião],">="&Visão_Geral!$E$4,TReunioes[Data da Reunião],"<="&Visão_Geral!$E$5,TReunioes[SDR],$A40) -> 7 | D40: =COUNTIFS(TReunioes[Data da Reunião],">="&Visão_Geral!$E$4,TReunioes[Data da Reunião],"<="&Visão_Geral!$E$5,TReunioes[SDR],$A40,TReunioes[Status],"Realizada") -> 2 | E40: =COUNTIFS(TReunioes[Data da Reunião],">="&Visão_Geral!$E$4,TReunioes[Data da Reunião],"<="&Visão_Geral!$E$5,TReunioes[SDR],$A40,TReunioes[Status],"Cancelada") -> 2 | F40: =COUNTIFS(TReunioes[Data da Reunião],">="&Visão_Geral!$E$4,TReunioes[Data da Reunião],"<="&Visão_Geral!$E$5,TReunioes[SDR],$A40,TReunioes[Status],"Remanejada") -> 0 | G40: =COUNTIFS(TPropostas[Data de Envio],">="&Visão_Geral!$E$4,TPropostas[Data de Envio],"<="&Visão_Geral!$E$5,TPropostas[SDR],$A40) -> 1 | H40: =COUNTIFS(TPropostas[Status],"Aprovada",TPropostas[Data de Retorno],">="&Visão_Geral!$E$4,TPropostas[Data de Retorno],"<="&Visão_Geral!$E$5,TPropostas[SDR],$A40) -> 0
A41: Gabriel Santana Barra - Matriz SP | B41: =COUNTIFS(TLigacoes[Data],">="&Visão_Geral!$E$4,TLigacoes[Data],"<="&Visão_Geral!$E$5,TLigacoes[Status],"Finalizada",TLigacoes[SDR],$A41) -> 34 | C41: =COUNTIFS(TReunioes[Data da Reunião],">="&Visão_Geral!$E$4,TReunioes[Data da Reunião],"<="&Visão_Geral!$E$5,TReunioes[SDR],$A41) -> 5 | D41: =COUNTIFS(TReunioes[Data da Reunião],">="&Visão_Geral!$E$4,TReunioes[Data da Reunião],"<="&Visão_Geral!$E$5,TReunioes[SDR],$A41,TReunioes[Status],"Realizada") -> 3 | E41: =COUNTIFS(TReunioes[Data da Reunião],">="&Visão_Geral!$E$4,TReunioes[Data da Reunião],"<="&Visão_Geral!$E$5,TReunioes[SDR],$A41,TReunioes[Status],"Cancelada") -> 2 | F41: =COUNTIFS(TReunioes[Data da Reunião],">="&Visão_Geral!$E$4,TReunioes[Data da Reunião],"<="&Visão_Geral!$E$5,TReunioes[SDR],$A41,TReunioes[Status],"Remanejada") -> 0 | G41: =COUNTIFS(TPropostas[Data de Envio],">="&Visão_Geral!$E$4,TPropostas[Data de Envio],"<="&Visão_Geral!$E$5,TPropostas[SDR],$A41) -> 8 | H41: =COUNTIFS(TPropostas[Status],"Aprovada",TPropostas[Data de Retorno],">="&Visão_Geral!$E$4,TPropostas[Data de Retorno],"<="&Visão_Geral!$E$5,TPropostas[SDR],$A41) -> 2
A42: Igor Vasconcelos - Matriz SP | B42: =COUNTIFS(TLigacoes[Data],">="&Visão_Geral!$E$4,TLigacoes[Data],"<="&Visão_Geral!$E$5,TLigacoes[Status],"Finalizada",TLigacoes[SDR],$A42) -> 0 | C42: =COUNTIFS(TReunioes[Data da Reunião],">="&Visão_Geral!$E$4,TReunioes[Data da Reunião],"<="&Visão_Geral!$E$5,TReunioes[SDR],$A42) -> 0 | D42: =COUNTIFS(TReunioes[Data da Reunião],">="&Visão_Geral!$E$4,TReunioes[Data da Reunião],"<="&Visão_Geral!$E$5,TReunioes[SDR],$A42,TReunioes[Status],"Realizada") -> 0 | E42: =COUNTIFS(TReunioes[Data da Reunião],">="&Visão_Geral!$E$4,TReunioes[Data da Reunião],"<="&Visão_Geral!$E$5,TReunioes[SDR],$A42,TReunioes[Status],"Cancelada") -> 0 | F42: =COUNTIFS(TReunioes[Data da Reunião],">="&Visão_Geral!$E$4,TReunioes[Data da Reunião],"<="&Visão_Geral!$E$5,TReunioes[SDR],$A42,TReunioes[Status],"Remanejada") -> 0 | G42: =COUNTIFS(TPropostas[Data de Envio],">="&Visão_Geral!$E$4,TPropostas[Data de Envio],"<="&Visão_Geral!$E$5,TPropostas[SDR],$A42) -> 0 | H42: =COUNTIFS(TPropostas[Status],"Aprovada",TPropostas[Data de Retorno],">="&Visão_Geral!$E$4,TPropostas[Data de Retorno],"<="&Visão_Geral!$E$5,TPropostas[SDR],$A42) -> 0
A43: Willian Gaia - filial Alphaville Vignatax | B43: =COUNTIFS(TLigacoes[Data],">="&Visão_Geral!$E$4,TLigacoes[Data],"<="&Visão_Geral!$E$5,TLigacoes[Status],"Finalizada",TLigacoes[SDR],$A43) -> 0 | C43: =COUNTIFS(TReunioes[Data da Reunião],">="&Visão_Geral!$E$4,TReunioes[Data da Reunião],"<="&Visão_Geral!$E$5,TReunioes[SDR],$A43) -> 0 | D43: =COUNTIFS(TReunioes[Data da Reunião],">="&Visão_Geral!$E$4,TReunioes[Data da Reunião],"<="&Visão_Geral!$E$5,TReunioes[SDR],$A43,TReunioes[Status],"Realizada") -> 0 | E43: =COUNTIFS(TReunioes[Data da Reunião],">="&Visão_Geral!$E$4,TReunioes[Data da Reunião],"<="&Visão_Geral!$E$5,TReunioes[SDR],$A43,TReunioes[Status],"Cancelada") -> 0 | F43: =COUNTIFS(TReunioes[Data da Reunião],">="&Visão_Geral!$E$4,TReunioes[Data da Reunião],"<="&Visão_Geral!$E$5,TReunioes[SDR],$A43,TReunioes[Status],"Remanejada") -> 0 | G43: =COUNTIFS(TPropostas[Data de Envio],">="&Visão_Geral!$E$4,TPropostas[Data de Envio],"<="&Visão_Geral!$E$5,TPropostas[SDR],$A43) -> 0 | H43: =COUNTIFS(TPropostas[Status],"Aprovada",TPropostas[Data de Retorno],">="&Visão_Geral!$E$4,TPropostas[Data de Retorno],"<="&Visão_Geral!$E$5,TPropostas[SDR],$A43) -> 0
A44: Paola Azevedo - Unidade PR | B44: =COUNTIFS(TLigacoes[Data],">="&Visão_Geral!$E$4,TLigacoes[Data],"<="&Visão_Geral!$E$5,TLigacoes[Status],"Finalizada",TLigacoes[SDR],$A44) -> 0 | C44: =COUNTIFS(TReunioes[Data da Reunião],">="&Visão_Geral!$E$4,TReunioes[Data da Reunião],"<="&Visão_Geral!$E$5,TReunioes[SDR],$A44) -> 0 | D44: =COUNTIFS(TReunioes[Data da Reunião],">="&Visão_Geral!$E$4,TReunioes[Data da Reunião],"<="&Visão_Geral!$E$5,TReunioes[SDR],$A44,TReunioes[Status],"Realizada") -> 0 | E44: =COUNTIFS(TReunioes[Data da Reunião],">="&Visão_Geral!$E$4,TReunioes[Data da Reunião],"<="&Visão_Geral!$E$5,TReunioes[SDR],$A44,TReunioes[Status],"Cancelada") -> 0 | F44: =COUNTIFS(TReunioes[Data da Reunião],">="&Visão_Geral!$E$4,TReunioes[Data da Reunião],"<="&Visão_Geral!$E$5,TReunioes[SDR],$A44,TReunioes[Status],"Remanejada") -> 0 | G44: =COUNTIFS(TPropostas[Data de Envio],">="&Visão_Geral!$E$4,TPropostas[Data de Envio],"<="&Visão_Geral!$E$5,TPropostas[SDR],$A44) -> 0 | H44: =COUNTIFS(TPropostas[Status],"Aprovada",TPropostas[Data de Retorno],">="&Visão_Geral!$E$4,TPropostas[Data de Retorno],"<="&Visão_Geral!$E$5,TPropostas[SDR],$A44) -> 0
A45: Cleber Scarparo - Filial Campinas | B45: =COUNTIFS(TLigacoes[Data],">="&Visão_Geral!$E$4,TLigacoes[Data],"<="&Visão_Geral!$E$5,TLigacoes[Status],"Finalizada",TLigacoes[SDR],$A45) -> 0 | C45: =COUNTIFS(TReunioes[Data da Reunião],">="&Visão_Geral!$E$4,TReunioes[Data da Reunião],"<="&Visão_Geral!$E$5,TReunioes[SDR],$A45) -> 0 | D45: =COUNTIFS(TReunioes[Data da Reunião],">="&Visão_Geral!$E$4,TReunioes[Data da Reunião],"<="&Visão_Geral!$E$5,TReunioes[SDR],$A45,TReunioes[Status],"Realizada") -> 0 | E45: =COUNTIFS(TReunioes[Data da Reunião],">="&Visão_Geral!$E$4,TReunioes[Data da Reunião],"<="&Visão_Geral!$E$5,TReunioes[SDR],$A45,TReunioes[Status],"Cancelada") -> 0 | F45: =COUNTIFS(TReunioes[Data da Reunião],">="&Visão_Geral!$E$4,TReunioes[Data da Reunião],"<="&Visão_Geral!$E$5,TReunioes[SDR],$A45,TReunioes[Status],"Remanejada") -> 0 | G45: =COUNTIFS(TPropostas[Data de Envio],">="&Visão_Geral!$E$4,TPropostas[Data de Envio],"<="&Visão_Geral!$E$5,TPropostas[SDR],$A45) -> 0 | H45: =COUNTIFS(TPropostas[Status],"Aprovada",TPropostas[Data de Retorno],">="&Visão_Geral!$E$4,TPropostas[Data de Retorno],"<="&Visão_Geral!$E$5,TPropostas[SDR],$A45) -> 0
A52: TABULAÇÃO DE LIGAÇÕES (período selecionado, só Finalizada)
A53: Motivo | B53: Quantidade | C53: % do Total
A54: Decisor não atendeu | B54: =COUNTIFS(TLigacoes[Data],">="&Visão_Geral!$E$4,TLigacoes[Data],"<="&Visão_Geral!$E$5,TLigacoes[Status],"Finalizada",TLigacoes[Tabulação],$A54) -> 134 | C54: =IFERROR($B54/(COUNTIFS(TLigacoes[Data],">="&Visão_Geral!$E$4,TLigacoes[Data],"<="&Visão_Geral!$E$5,TLigacoes[Status],"Finalizada")),0) -> 0.56540084
A55: Recepcionista não transferiu | B55: =COUNTIFS(TLigacoes[Data],">="&Visão_Geral!$E$4,TLigacoes[Data],"<="&Visão_Geral!$E$5,TLigacoes[Status],"Finalizada",TLigacoes[Tabulação],$A55) -> 64 | C55: =IFERROR($B55/(COUNTIFS(TLigacoes[Data],">="&Visão_Geral!$E$4,TLigacoes[Data],"<="&Visão_Geral!$E$5,TLigacoes[Status],"Finalizada")),0) -> 0.27004219
A56: Ligação caiu | B56: =COUNTIFS(TLigacoes[Data],">="&Visão_Geral!$E$4,TLigacoes[Data],"<="&Visão_Geral!$E$5,TLigacoes[Status],"Finalizada",TLigacoes[Tabulação],$A56) -> 4 | C56: =IFERROR($B56/(COUNTIFS(TLigacoes[Data],">="&Visão_Geral!$E$4,TLigacoes[Data],"<="&Visão_Geral!$E$5,TLigacoes[Status],"Finalizada")),0) -> 0.016877637
A57: Decisor ausente/férias | B57: =COUNTIFS(TLigacoes[Data],">="&Visão_Geral!$E$4,TLigacoes[Data],"<="&Visão_Geral!$E$5,TLigacoes[Status],"Finalizada",TLigacoes[Tabulação],$A57) -> 11 | C57: =IFERROR($B57/(COUNTIFS(TLigacoes[Data],">="&Visão_Geral!$E$4,TLigacoes[Data],"<="&Visão_Geral!$E$5,TLigacoes[Status],"Finalizada")),0) -> 0.046413502
...

Sheet Resumo_1_Semestre
A1: RESUMO DO 1º SEMESTRE — REUNIÕES E PROPOSTAS
A2: Números consolidados de Janeiro a Junho, com base no histórico mensal por SDR (aba de referência: planilha "junho").
A4: TOTAIS DO SEMESTRE POR MÊS
A5: Mês | B5: Reuniões Agendadas | C5: Reuniões Realizadas | D5: Propostas Enviadas | E5: Negócios Fechados
A6: Janeiro | B6: 191 | C6: 100 | D6: 46 | E6: 6
A7: Fevereiro | B7: 312 | C7: 132 | D7: 82 | E7: 13
A8: Março | B8: 351 | C8: 207 | D8: 134 | E8: 25
A9: Abril | B9: 288 | C9: 113 | D9: 94 | E9: 11
A10: Maio | B10: 374 | C10: 175 | D10: 131 | E10: 33
A11: Junho | B11: 245 | C11: 124 | D11: 103 | E11: 28
A12: TOTAL 1º SEMESTRE | B12: 1761 | C12: 851 | D12: 590 | E12: 116
A15: DETALHE POR SDR E MÊS
A16: Mês | B16: Quarter | C16: SDR | D16: Mês de Contratação | E16: Estado | F16: Agendado | G16: Realizado | H16: Proposta | I16: Fechado | J16: Meta Ag. | K16: Meta Real. | L16: Status
A17: Janeiro | B17: Q1 | C17: Nathália | D17: 45962 | E17: PR | F17: 19 | G17: 11 | H17: 9 | I17: 0 | J17: 60 | K17: 32 | L17: Desligado
A18: Janeiro | B18: Q1 | C18: Ana Belle | D18: 46023 | E18: PR | F18: 11 | G18: 0 | H18: 0 | I18: 0 | J18: 60 | K18: 32 | L18: Ativo
A19: Janeiro | B19: Q1 | C19: Victor | D19: 45992 | E19: MG | F19: 5 | G19: 3 | H19: 0 | I19: 0 | J19: 60 | K19: 32 | L19: Desligado
A20: Janeiro | B20: Q1 | C20: Gabriela | E20: RS | F20: 8 | G20: 10 | H20: 5 | I20: 0 | J20: 60 | K20: 32 | L20: Desligado
A21: Janeiro | B21: Q1 | C21: Clara | E21: ALPHA | F21: 14 | G21: 4 | H21: 0 | I21: 0 | J21: 60 | K21: 32 | L21: Desligado
A22: Janeiro | B22: Q1 | C22: Alessandra | E22: CAMPINAS | F22: 15 | G22: 2 | H22: 0 | I22: 0 | J22: 60 | K22: 32 | L22: Desligado
A23: Janeiro | B23: Q1 | C23: Leticia Mascarin | D23: 45778 | E23: CAMPINAS | F23: 17 | G23: 4 | H23: 2 | I23: 0 | J23: 60 | K23: 32 | L23: Ativo
A24: Janeiro | B24: Q1 | C24: Ryan | E24: CAMPINAS | F24: 11 | G24: 3 | H24: 0 | I24: 0 | J24: 60 | K24: 32 | L24: Desligado
A25: Janeiro | B25: Q1 | C25: Lawanny | D25: 45992 | E25: ALPHA | F25: 20 | G25: 1 | H25: 6 | I25: 0 | J25: 60 | K25: 32 | L25: Ativo
A26: Janeiro | B26: Q1 | C26: Ana Beatriz | D26: 45139 | E26: ALPHA | F26: 0 | G26: 1 | H26: 1 | I26: 1 | J26: 60 | K26: 32 | L26: Ativo
A27: Janeiro | B27: Q1 | C27: Gabriel Santana | D27: 45627 | E27: MATRIZ | F27: 3 | G27: 3 | H27: 0 | I27: 0 | J27: 60 | K27: 32 | L27: Ativo
A28: Janeiro | B28: Q1 | C28: Ana Karolayne | D28: 45870 | E28: MATRIZ | F28: 19 | G28: 23 | H28: 4 | I28: 0 | J28: 60 | K28: 32 | L28: Ativo
A29: Janeiro | B29: Q1 | C29: Kailany | D29: 45962 | E29: MATRIZ | F29: 25 | G29: 14 | H29: 7 | I29: 0 | J29: 60 | K29: 32 | L29: Ativo
A30: Janeiro | B30: Q1 | C30: Michelle | D30: 45931 | E30: MATRIZ | F30: 24 | G30: 20 | H30: 11 | I30: 1 | J30: 60 | K30: 32 | L30: Ativo
A31: Janeiro | B31: Q1 | C31: Igor Vasconcelos | E31: MATRIZ | F31: 0 | G31: 1 | H31: 1 | I31: 4 | L31: Ativo
A32: Fevereiro | B32: Q1 | C32: Nathália | D32: 45962 | E32: PR | F32: 42 | G32: 14 | H32: 10 | I32: 0 | J32: 60 | K32: 32 | L32: Desligado
A33: Fevereiro | B33: Q1 | C33: Ana Belle | D33: 46023 | E33: PR | F33: 25 | G33: 4 | H33: 4 | I33: 0 | J33: 60 | K33: 32 | L33: Ativo
A34: Fevereiro | B34: Q1 | C34: Victor | D34: 45992 | E34: MG | F34: 29 | G34: 5 | H34: 0 | I34: 1 | J34: 60 | K34: 32 | L34: Desligado
A35: Fevereiro | B35: Q1 | C35: Fabiola | E35: MG | F35: 1 | G35: 0 | H35: 0 | I35: 0 | J35: 60 | K35: 32 | L35: Desligado
A36: Fevereiro | B36: Q1 | C36: Maria | D36: 46023 | E36: RS | F36: 3 | G36: 0 | H36: 0 | I36: 0 | J36: 60 | K36: 32 | L36: Ativo
A37: Fevereiro | B37: Q1 | C37: Clara | E37: ALPHA | F37: 16 | G37: 4 | H37: 0 | I37: 0 | J37: 60 | K37: 32 | L37: Desligado
A38: Fevereiro | B38: Q1 | C38: Alessandra | E38: CAMPINAS | F38: 17 | G38: 1 | H38: 0 | I38: 0 | J38: 60 | K38: 32 | L38: Desligado
A39: Fevereiro | B39: Q1 | C39: Leticia Mascarin | D39: 45778 | E39: CAMPINAS | F39: 21 | G39: 12 | H39: 0 | I39: 0 | J39: 60 | K39: 32 | L39: Ativo
A40: Fevereiro | B40: Q1 | C40: Ryan | E40: CAMPINAS | F40: 14 | G40: 7 | H40: 0 | I40: 0 | J40: 60 | K40: 32 | L40: Desligado
A41: Fevereiro | B41: Q1 | C41: Lawanny | D41: 45992 | E41: ALPHA | F41: 19 | G41: 12 | H41: 3 | I41: 0 | J41: 60 | K41: 32 | L41: Ativo
A42: Fevereiro | B42: Q1 | C42: Ana Beatriz | D42: 45139 | E42: ALPHA | F42: 11 | G42: 7 | H42: 0 | I42: 0 | J42: 60 | K42: 32 | L42: Ativo
A43: Fevereiro | B43: Q1 | C43: Gabriel Santana | D43: 45627 | E43: MATRIZ | F43: 29 | G43: 22 | H43: 25 | I43: 5 | J43: 60 | K43: 32 | L43: Ativo
...

Sheet Lançamento_Reuniões
A1: Data da Reunião | B1: Empresa | C1: Segmento | D1: CNPJ | E1: Nome do Responsável | F1: Cargo | G1: Cidade | H1: Estado | I1: SDR | J1: Consultor/Especialista | K1: Status | L1: Teve Proposta | M1: Tipo de Proposta | N1: Negócio Fechado
A2: 46217.5 | B2: CONSTRUTORA CLARK LTDA | C2: Construtora | D2: 65.527.939/0001-54 | E2: Lourdes | F2: RH | G2: São Paulo | H2: SP | I2: Ana Karolayne - Matriz SP | J2: Pamela | K2: Cancelada
A3: 46213.5 | B3: XILOLITE S/A | C3: Prestadora de serviços | D3: Não localizado | E3: Fabiano | F3: RH | G3: Brumado | H3: BA | I3: Ana Karolayne - Matriz SP | J3: Igor e Cinthia | K3: Realizada | L3: Sim
A4: 46216.5 | B4: MINUSA TRATORPEÇAS | C4: Prestadora de serviços | D4: 84.943.067/0001-50 | E4: Luciana | F4: RH | G4: Lages | H4: SC | I4: Kailany Santos da Silva - Matriz SP | J4: Paola e Ana Beatriz | K4: Cancelada
A5: 46204.5 | B5: PBL ASSESSORIA DE COMERCIO EXTERIOR LTDA | C5: Prestadora de serviços | D5: 57.108.730/0001-28 | E5: Tatiana | F5: Contábil | G5: São Paulo | H5: SP | I5: Igor Souza Ferreira - Matriz SP | J5: Pamela | K5: Realizada | L5: Sim
A6: 46210.5 | B6: TRANSMAGNO TRANSPORTES RODOVIARIOS LTDA | C6: Transportes | D6: 03.056.739/0001-03 | E6: Benjamim | F6: Jurídico | G6: Goiânia | H6: GO | I6: Ana Karolayne - Matriz SP | J6: Paola | K6: Cancelada
A7: 46206.5 | B7: UY3 SOCIEDADE DE CREDITO DIRETO S/A | C7: Investimento | D7: 39.587.424/0001-30 | E7: Dayana Nogueira | F7: Jurídico | G7: Porto Alegre | H7: RS | I7: Ana Karolayne - Matriz SP | J7: Tayna Bregnoli | K7: Realizada
A8: 46219.5 | B8: MULTIPRINT ETIQUETAS LTDA | C8: Prestadora de serviços | D8: 72.499.072/0001-36 | E8: Renata | F8: RH | G8: Jaraguá do Sul | H8: SC | I8: Ana Karolayne - Matriz SP | J8: Igor Vasconcelos | K8: Cancelada
A9: 46212.5 | B9: MANUFATURA DE METAIS MAGNET LTDA | C9: Indústria em geral | D9: 61.155.529/0001-79 | E9: Edson | F9: Jurídico | G9: São Bernardo do Campo | H9: SP | I9: Ana Karolayne - Matriz SP | J9: Paola e Willian Gaia | K9: Realizada
A10: 46205.5 | B10: TERRITORIAL TRANSPORTES E EMPREENDIMENTOS LTDA | C10: Transportes | D10: 03.889.255/0001-45 | E10: Eva | F10: Jurídico | G10: Santa Luzia | H10: MG | I10: Ana Karolayne - Matriz SP | J10: Paola e João | K10: Realizada
A11: 46226.5 | B11: TGM MAQUINAS E EQUIPAMENTOS | C11: Indústria em geral | D11: 02.355.505/0001-02 | E11: Adilson | F11: Jurídico | G11: Corupá | H11: SC | I11: Michelle Valente Araujo - Matriz SP | J11: Paola e João | K11: Futura
B12: CONCESSIONARIA DO AEROPORTO INTERNACIONAL DE GUARULHOS SA | C12: Transportes | G12: Guarulhos | H12: SP | I12: Gabriel Santana Barra - Matriz SP | J12: Paulo Vigna, Tayna Bregnoli e Pamela Pedro | K12: Realizada | L12: Sim
A13: 46204 | B13: ASSOCIACAO EDUCACIONAL LECRISTO | C13: Educação | D13: 80.790.298/0001-10 | E13: Paolla Fragnan | F13: Não informado | G13: São Paulo | H13: SP | I13: Gabriel Santana Barra - Matriz SP | J13: Tayna Bregnoli e Pamela Pedro | K13: Realizada
A14: 46206 | B14: ASSOCIACAO EDUCACIONAL LECRISTO | C14: Educação | D14: 80.790.298/0001-10 | E14: Paolla Fragnan | F14: Não informado | G14: São Paulo | H14: SP | I14: Gabriel Santana Barra - Matriz SP | J14: Tayna Bregnoli e Marlene teixeira | K14: Realizada
A15: 46213.5 | B15: PISAFIX ADESIVOS E SELANTES LTDA | C15: Indústria em geral | D15: 15.265.287/0001-59 | E15: Vagner | F15: Diretor | G15: Balneário Rincão | H15: SC | I15: Ana Karolayne - Matriz SP | J15: Pamela e Joao Victor | K15: Realizada | L15: Sim
A16: 46213.5 | B16: VIDEPLAST INDUSTRIA DE EMBALAGENS LTDA | C16: Indústria em geral | D16: 79.687.588/0001-53 | E16: Mariangela | F16: Gerente de RH | G16: Videira | H16: SC | I16: Gabriel Santana Barra - Matriz SP | J16: Pamela Pedro e Igor Vasconcelos | K16: Cancelada
A17: 46216.5 | B17: TRINITY ENERGIAS RENOVAVEIS S.A | C17: Energia | D17: 17.077.752/0001-53 | E17: Flavio | F17: Jurídico | G17: São Paulo | H17: SP | I17: Gabriel Santana Barra - Matriz SP | J17: Pamela Pedro e Mayara Leite | K17: Cancelada
A18: 46217.5 | B18: TRANSPORTES MARVEL LTDA | C18: órgãos públicos | D18: 83.084.301/0001-78 | E18: Andreia | F18: Segurança do Trabalho | G18: Chapecó | H18: SC | I18: Ana Karolayne - Matriz SP | J18: Igor Vasconcelos | K18: Realizada
A19: 46223.5 | B19: LISBOA MARCENARIA E VIDRACARIA LTDA | C19: Indústria de Manufatura | D19: 04.726.003/0001-68 | E19: Allan | F19: RH | G19: Mossoró | H19: RN | I19: Kailany Santos da Silva - Matriz SP | J19: Paola e Igor | K19: Futura
A20: 46218.5 | B20: FG LABORATORIO OTICO LTDA | C20: Saúde | D20: 03.495.075/0001-89 | E20: Conceição | F20: Financeiro | G20: Salvador | H20: BA | I20: Kailany Santos da Silva - Matriz SP | J20: Cleber | K20: Cancelada
B21: INDAIAL PAPEL EMBALAGENS LTDA | I21: Ana Karolayne - Matriz SP | K21: Realizada | L21: Sim
A22: 46219.5 | B22: ALEGRAF INDUSTRIA GRAFICA LTDA | C22: Indústria em geral | D22: 03.794.550/0001-18 | E22: Flavia | F22: Administrativo | G22: Cuiabá | H22: MT | I22: Ana Karolayne - Matriz SP | J22: Paola e William | K22: Cancelada
A23: 46224.5 | B23: AGRO INDUSTRIAL ITUBERA | C23: Agronegócio | D23: 13.543.822/0001-60 | E23: Elionora | F23: Coordenadora de RH | G23: Ituberá | H23: BA | I23: Kailany Santos da Silva - Matriz SP | J23: Igor | K23: Futura
A24: 46209 | B24: DR. LUIZ NAZAR - indicação Dr. Ernesto | G24: São Paulo | H24: SP | I24: Gabriel Santana Barra - Matriz SP | K24: Realizada
A25: 46220.5 | B25: CG TELHAS COMERCIO, INDUSTRIA E SERVICOS DE FERRO E ACO LTDA | C25: Indústria em geral | D25: 26.861.930/0001-23 | E25: Lucimara | F25: RH | G25: Campo Grande | H25: MS | I25: Ana Karolayne - Matriz SP | J25: Igor Vasconcelos | K25: Cancelada
A26: 46225.5 | B26: GALWAN CONSTRUTORA E INCORPORADORA LTDA | C26: Construtora | D26: 31.705.692/0001-05 | E26: Barbara | F26: Jurídico | G26: Vila Velha | H26: ES | I26: Kailany Santos da Silva - Matriz SP | J26: Paola | K26: Futura
A27: 46211 | B27: Agropecuaria Irmaos Walker Ltda | C27: Agronegócio | D27: 44.666.256/0001-08 | E27: Willian | F27: Fiscal | G27: Luís Eduardo Magalhães | H27: BA | I27: Kailany Santos da Silva - Matriz SP | J27: Paola e João | K27: Realizada | L27: Sim
A28: 46216 | B28: UHY BENDORAYTES & CIA AUDITORES INDEPENDENTES | I28: Kailany Santos da Silva - Matriz SP | K28: Realizada | L28: Não
A29: 46223.5 | B29: Orcali Servicos de Seguranca Ltda | C29: Segurança | D29: 83.930.214/0001-94 | E29: Ana Righetto | F29: Compliance | G29: Florianópolis | H29: SC | I29: Kailany Santos da Silva - Matriz SP | J29: Pamela
A30: 46234.5 | B30: LEROY MERLIN COMPANHIA DE BRICOLAGEM S/A | C30: Comércio Varejista | D30: 01.438.784/0001-05 | E30: Cristiane | F30: Jurídico | G30: São Paulo | H30: SP | I30: Kailany Santos da Silva - Matriz SP | J30: Pamela e Tayna
A31: 46239.5 | B31: CIVIL ENGENHARIA LTDA | C31: Construtora | D31: 01.710.170/0001-22 | E31: Bruna | F31: RH | G31: Brasília | H31: DF | I31: Kailany Santos da Silva - Matriz SP | J31: Paola e Igor
B32: CONCESSIONARIA DO AEROPORTO INTERNACIONAL DE GUARULHOS SA | I32: Gabriel Santana Barra - Matriz SP
A33: 46223.5 | B33: Granjas Sao Jose | C33: Agronegócio | D33: 07.591.258/0001-59 | E33: Henrique | F33: Jurídico | G33: Horizonte | H33: CE | I33: Kailany Santos da Silva - Matriz SP | J33: Paola e João
B34: TERRA LUZ TRANSPORTES S/A | I34: Ana Karolayne - Matriz SP
A35: 46224.5 | B35: AMMAC INDUSTRIA E COMERCIO DE ALIMENTOS LTDA | C35: Indústria em geral | D35: 63.737.852/0001-86 | E35: Lara | F35: RH | G35: Manaus | H35: AM | I35: Gabriel Santana Barra - Matriz SP | J35: Pamela Pedro
A36: 46241.5 | B36: TRANSPORTES F.S. S.A | C36: Transportes | D36: 33.943.267/0001-71 | E36: Carlos | F36: Fiscal | G36: Duque de Caxias | H36: RJ | I36: Ana Karolayne - Matriz SP | J36: Edilaine
B37: Produmaster Industria De Compostos Plasticos Ltda | I37: Kailany Santos da Silva - Matriz SP | K37: Realizada | L37: Não
A38: 46219.5 | B38: Belluno Pagamentos | C38: Não localizado | D38: 81.514.473/0001-09 | E38: Arituza | F38: Financeiro | G38: Não localizado | H38: Não localizado | I38: Michelle Valente Araujo - Matriz SP | J38: Paola e Willian | K38: Realizada | L38: Sim | M38: VIGNATAX - REVISÃO FISCAL
A39: 46255.5 | B39: CNH INDUSTRIAL BRASIL LTDA. | C39: Indústria em geral | D39: 01.844.555/0001-82 | E39: Claudio | F39: Compliance | G39: Nova Lima | H39: MG | I39: Ana Karolayne - Matriz SP | J39: Tayna Bregnoli e Pamela
A40: 46226.5 | B40: SKYMARK GERENCIAMENTO DE RISCOS LTDA | C40: Tecnologia | D40: 04.755.777/0001-17 | E40: Clarice e Eduard | F40: Não informado | G40: Osasco | H40: SP | I40: Kailany Santos da Silva - Matriz SP | J40: Pamela, Tayna e Edilaine
...

Sheet Lançamento_Ligações
A1: Data | B1: SDR | C1: Empresa | D1: Status | E1: Tabulação | F1: Observação
A2: 46211 | B2: Kailany Santos da Silva - Matriz SP | C2: Jhonrob Silos E Secadores | D2: Finalizada | E2: Recepcionista não transferiu | F2: (66) 3515-7005 - buscar financeiro contasapagar@jhonrob.com.br - geovana 08/07 - falei com a recepcionista e ela disse que a geovana resp pelo financ
A3: 46211 | B3: Kailany Santos da Silva - Matriz SP | C3: Implantus Materiais Cirúrgicos | D3: Finalizada | E3: Decisor não atendeu | F3: (91) 3222-8368 - Buscar sergio resp financeiro de preferencia a tarde 08/07 - uma pessoa do financeiro disse que ia transferir para o Sergio e deslig
A4: 46211 | B4: Kailany Santos da Silva - Matriz SP | C4: Motech Do Brasil Industria De Plasticos Ltda | D4: Finalizada | E4: Decisor não atendeu | F4: 15) 3414-0350 Buscar barbara do rh ou guilherme juridico 08/07 - Guilherme mais uma vez não estava, buscar financeiro
A5: 46211 | B5: Kailany Santos da Silva - Matriz SP | C5: TODO TETO CASA & CONSTRUCAO LTDA | D5: Finalizada | E5: Recusa/Objeção | F5: 1635131800 - buscar Edivaldo resp financeiro 08/07 - Falei com Edvaldo e ele passou para a Thalita resp pela area tributaria, e ela foi bem grossa,
A6: 46211 | B6: Kailany Santos da Silva - Matriz SP | C6: INTERCOMM LOGÍSTICA S/A | D6: Finalizada | E6: Ligação caiu | F6: (27) 2121-5600 - caiu no setor comercial e recepcionista disse que ia passar o recado da reunião para Livia
A7: 46211 | B7: Kailany Santos da Silva - Matriz SP | C7: GALWAN CONSTRUTORA E INCORPORADORA LTDA | D7: Finalizada | E7: Reunião marcada | F7: Retornar para barbara 08/07 - reunião alinhada com Barbara no dia 23/07 as 16h
A8: 46211 | B8: Kailany Santos da Silva - Matriz SP | C8: Ponto Norte Comercio Transporte Logistica Ltda | D8: Finalizada | E8: Recepcionista não transferiu | F8: 9140088600 buscar rh novamente 08/07 - recepcionista me passou para setor do rh porem ficou na ura ate cair sozinha a chamada
A9: 46211 | B9: Kailany Santos da Silva - Matriz SP | C9: Bomboleo Brasil | D9: Finalizada | E9: Recepcionista não transferiu | F9: 62 3282-8520 buscar financeiro 10/06 - Sem sucesso 08/07 - recepcionista da area financeira falou que o rep bruno não estava na mesa dele e pediu par
A10: 46211 | B10: Kailany Santos da Silva - Matriz SP | C10: Vmg Bioenergia | D10: Finalizada | E10: Decisor não atendeu | F10: (64) 3632-1276 - coloquei o ramal do jonathan e ele disse que a empresa ta sem financeiro no momento e que questões tributarias não seriam com ele
A11: 46211 | B11: Kailany Santos da Silva - Matriz SP | C11: Vmg Bioenergia | D11: Finalizada | E11: Recepcionista não transferiu | F11: (64) 3632-1276 - buscar financeiro/ 109 - Jonatas almoxarifadop@vmgbioenergia.com.br 08/07 - Recepcionista falou que resp financeiro é o Jonathas por
A12: 46210 | B12: Kailany Santos da Silva - Matriz SP | C12: SANTA CASA DE MISERICORDIA DE SANTO AMARO | D12: Finalizada | E12: Decisor ausente/férias | F12: 1155258700 - buscar financeiro 07/07 - resp pelo contabilidade está de ferias e só retorna no inicio do prox mes
A13: 46210 | B13: Kailany Santos da Silva - Matriz SP | C13: PLANATC TECNOLOGIA | D13: Finalizada | E13: Recepcionista não transferiu | F13: (11) 2141-4891 - somente chamou, buscar financeiro ou rh. 11/06 - apertei na opção recursos humanos e desligou, retorno 07/07 - fui na opção financ
... A238: 46204 | B238: Ana Karolayne - Matriz SP | C238: CONSTRUTORA CLARK LTDA | D238: Finalizada | E238: Decisor não atendeu | F238: Ligação 11 99504-0536- Retomar o contato caso ela não responda

Sheet Propostas_Enviadas
A1: PROPOSTAS ENVIADAS
A2: Controle de propostas enviadas e status de negociação.
A4: TOTAL ENVIADAS | C4: EM NEGOCIAÇÃO | E4: APROVADAS | G4: RECUSADAS
A5: =COUNTA(TPropostas[Empresa]) -> 12 | C5: =COUNTIF(TPropostas[Status],"Em Negociação") -> 2 | E5: =COUNTIF(TPropostas[Status],"Aprovada") -> 2 | G5: =COUNTIF(TPropostas[Status],"Recusada") -> 2
A7: TAXA DE APROVAÇÃO
A8: =IFERROR(COUNTIF(TPropostas[Status],"Aprovada")/COUNTA(TPropostas[Empresa]),0) -> 0.16666667
A11: Data de Envio | B11: Empresa | C11: SDR | D11: Tipo de Proposta | E11: Valor Estimado (R$) | F11: Status | G11: Data de Retorno | H11: Observação
A12: 46210 | B12: Herbert Passos Filho | C12: Gabriel Santana Barra - Matriz SP | D12: VAA - CONTENCIOSO TRIBUTÁRIO | E12: 10000 | F12: Em Negociação
A13: 46210 | B13: INSTITUTO RONALD MCDONALD DE APOIO A CRIANCA | C13: Gabriel Santana Barra - Matriz SP | D13: DUE DILIGENCE | E13: 1500 | F13: Aprovada | G13: 46210
A14: 46204 | B14: ASSOCIACAO EDUCACIONAL LECRISTO | C14: Gabriel Santana Barra - Matriz SP | D14: treinamento | E14: 3500 | F14: Enviada
A15: 46204 | B15: UNIMED SERGIPE - COOPERATIVA DE TRABALHO MÉDICO | C15: Gabriel Santana Barra - Matriz SP | D15: INVESTIGAÇÃO CC | E15: 590 | F15: Aprovada | G15: 46210
A16: 46210 | B16: DR. LUIZ NAZAR - indicação Dr. Ernesto | C16: Gabriel Santana Barra - Matriz SP | D16: VAA - PENAL | E16: 14000 | F16: Em Negociação
A17: 46205 | B17: Confederação Brasileira de Tênis de Mesa | C17: Gabriel Santana Barra - Matriz SP | D17: BPO - COMPLIANCE CONTROL | E17: 4200 | F17: Recusada | G17: 46210 | H17: Concorrente - Dra. Itala, me atendeu e informou que escolheram outro fornecedor
A18: 46205 | B18: Confederação Brasileira de Tênis de Mesa | C18: Gabriel Santana Barra - Matriz SP | D18: BPO - COMPLIANCE CONTROL | E18: 4200 | F18: Recusada | G18: 46210 | H18: Desistência
A19: 46205 | B19: COBASI COMERCIO DE PROD BASICOS E INDUSTRIALIZADOS LTDA | C19: Kailany Santos da Silva - Matriz SP | D19: VAA - CONTENCIOSO TRABALHISTA | F19: Enviada
A20: 46204 | B20: ASSOCIACAO EDUCACIONAL LECRISTO | C20: Gabriel Santana Barra - Matriz SP | D20: treinamento | E20: 5500 | F20: Enviada
A21: 46209 | B21: UY3 SOCIEDADE DE CREDITO DIRETO S/A | C21: Ana Karolayne - Matriz SP | D21: IMPLEMENTAÇÃO DE LGPD | E21: 850 | F21: Enviada
A22: 46209 | B22: Territorial Transportes e Empreendimentos | C22: Ana Karolayne - Matriz SP | D22: IMPLEMENTAÇÃO DE LGPD | E22: 2700 | F22: Enviada

Sheet Equipe_SDR
A1: SDR | B1: Mês de Contratação | C1: Status
A2: Igor Souza Ferreira - Matriz SP | B2: 46054 | C2: Inativo
A3: Maria Furtado - Filial RS | B3: 46023 | C3: Ativo
A4: Kailany Santos da Silva - Matriz SP | B4: 45962 | C4: Ativo
A5: Michelle Valente Araujo - Matriz SP | B5: 45931 | C5: Inativo
A6: Ana Belle - Filial PR | B6: 46023 | C6: Ativo
A7: Gabriel Santana Barra - Matriz SP | B7: 45627 | C7: Ativo
A8: Ana Karolayne - Matriz SP | B8: 45870 | C8: Ativo
A9: Lawanny Souza Brasil Luz - Filial Alpha | B9: 45992 | C9: Ativo
A10: Railanne Rosario do Carmo - Filial Alpha | B10: 46113 | C10: Ativo
A11: Larissa Santos - Filial Porto Alegre | B11: 46147 | C11: Ativo
A12: Ana Beatriz Soares Silva - Filial Alpha | C12: Ativo
A13: Leticia Pereira Mascarin - Filial Campinas | C13: Ativo
A15: Obs.: datas de contratação informadas pelo usuário em 17/07/2026. Ana Beatriz Soares Silva e Leticia Pereira Mascarin aparecem nos lançamentos mas não tiveram data de contratação informada (destacado em amarelo) — preencher quando disponível.

Sheet Listas
A1: SDR | C1: Status | E1: SimNao | G1: StatusProposta | I1: TipoVisao | K1: Setor | M1: TipoProposta | O1: StatusAtividade | Q1: TabulacaoLigacao | S1: Estado
A2: Larissa Santos - Filial Porto Alegre | C2: Realizada | E2: Sim | G2: Enviada | I2: Diário | K2: Agronegócio | M2: BPO - COMPLIANCE CONTROL | O2: Finalizada | Q2: Decisor não atendeu | S2: AC
A3: Railanne Rosario do Carmo - Filial Alpha | C3: Cancelada | E3: Não | G3: Em Negociação | I3: Semanal | K3: Alimentício | M3: CANAL DE DENUNCIA | O3: Não Finalizada | Q3: Recepcionista não transferiu | S3: AL
A4: Maria Furtado - Filial RS | C4: Remanejada | G4: Aprovada | I4: Mensal | K4: Automotivo | M4: CIVEL | Q4: Ligação caiu | S4: AP
A5: Ana Belle - Filial PR | C5: Futura | G5: Recusada | K5: Bancos | M5: COMPLIANCE CONTROL | Q5: Decisor ausente/férias | S5: AM
A6: Lawanny Souza Brasil Luz - Filial Alpha | K6: Comércio Atacadista | M6: COMPLIANCE NR1+ | Q6: Recusa/Objeção | S6: BA
A7: Ana Karolayne - Matriz SP | K7: Comércio Varejista | M7: COMPLIANCE PREVIDENCIÁRIO | Q7: Sem sucesso | S7: CE
A8: Kailany Santos da Silva - Matriz SP | K8: Construtora | M8: DIAGNÓSTICO - REFORMA TRIBUTÁRIA | Q8: Reunião marcada | S8: DF
A9: Gabriel Santana Barra - Matriz SP | K9: Distribuidor | M9: DIFAL | Q9: Retorno agendado | S9: ES
A10: Igor Vasconcelos - Matriz SP | K10: Educação | M10: DOSSIÊ | S10: GO
A11: Willian Gaia - filial Alphaville Vignatax | K11: Energia | M11: DPO AS A SERVICE | S11: MA
A12: Paola Azevedo - Unidade PR | K12: Escritório de Advocacia | M12: DUE DILIGENCE | S12: MT
A13: Cleber Scarparo - Filial Campinas | K13: Escritório de Contabilidade | M13: Elaboração de Políticas - Compliance Control | S13: MS
A14: Leticia Pereira | K14: Esporte | M14: GESTÃO DE TERCEIROS CC | S14: MG
A15: Maria Helena | K15: Exportadora | M15: GESTÃO DO CANAL DE DENÚNCIAS | S15: PA
A16: Milena Faria | K16: Fábrica | M16: IMPLEMENTAÇÃO COMPLIANCE | S16: PB
A17: Nathália Santos | K17: Farmacêutico | M17: IMPLEMENTAÇÃO DE LGPD | S17: PR
A18: Victor Drumond | K18: Imobiliária | M18: INVESTIGAÇÃO CC | S18: PE
K19: Importadora e Exportadora | M19: LC - COMPLETO | S19: PI
K20: Indústria de Manufatura | M20: LC - CONTENCIOSO | S20: RJ
K21: Indústria em geral | M21: LC - CONTRATOS | S21: RN
K22: Indústria fabricante de máquinas | M22: LC - GESTÃO DE TERCEIROS | S22: RS
K23: Investimento | M23: LC - PROCURAÇÕES | S23: RO
K24: Logística | M24: LEGAL AUDIT | S24: RR
K25: Metalúrgica | M25: LEGAL ÉTICA | S25: SC
K26: Mineradora | M26: LEGAL TRAINING | S26: SP
K27: Órgãos Públicos | M27: lucro | S27: SE
K28: Prestadora de Serviços | M28: PARCERIA CC | S28: TO
K29: Saúde | M29: PARCERIA LC E LE
K30: Seguradoras | M30: PARCERIA VAA
K31: Segurança | M31: PARCERIA VTAX
K32: Tecnologia | M32: PARECER
K33: Telecomunicações | M33: PROJETO VT
K34: Transportes | M34: TESE LUCRO PRESUMIDO
K35: Pessoa Física | M35: treinamento
M36: TREINAMENTO DE ASSÉDIO MORAL E SEXUAL
M37: TREINAMENTO DE CÓDIGO DE CONDUTA
M38: TREINAMENTO NR-1
M39: VAA - ADMINISTRATIVO
M40: VAA - AMBIENTAL
...
